<?xml version="1.0" ?>
<!-- Homemade by Francesco Petracci -->
<robot name="rc_car_fra">
  <material name="Red">
    <color rgba="1.0 0 0 1.0"/>
  </material>
  <material name="Green">
    <color rgba="0 1.0 0 1.0"/>
  </material>
  <material name="Black">
    <color rgba="0 0 0 1.0"/>
  </material>
  <!-- Main body -->
  <link name="base_link">
    <inertial>
      <mass value="0.2"/>
      <origin xyz="0 0 0"/>
      <inertia ixx="0.2" ixy="0.0" ixz="0.0" iyy="0.2" iyz="0.0" izz="0.2"/>
    </inertial>
    <visual>
      <origin rpy="0 0 0" xyz="0 0 0"/>
      <geometry>
        <box size="0.3 0.15 0.08"/>
      </geometry>
      <material name="Red"/>
    </visual>
    <collision>
      <origin rpy="0 0 0" xyz="0 0 0"/>
      <geometry>
        <box size="0.3 0.15 0.08"/>
      </geometry>
    </collision>
  </link>
  <!-- Steering joint -->
  <joint name="steering_joint" type="continuous">
    <axis xyz="0 0 1"/>
    <parent link="base_link"/>
    <child link="steering_link"/>
    <origin xyz="0.16 0.0 -0.1"/>
  </joint>
  <link name="steering_link">
    <inertial>
      <mass value="0.01"/>
      <origin xyz="0 0 0"/>
      <inertia ixx="0.01" ixy="0.0" ixz="0.0" iyy="0.01" iyz="0.0" izz="0.01"/>
    </inertial>
    <visual>
      <geometry>
        <box size="0.015 0.15 0.005"/>
      </geometry>
      <material name="Green"/>
    </visual>
    <collision>
      <geometry>
        <box size="0.015 0.15 0.005"/>
      </geometry>
    </collision>
  </link>
  <!-- the front left wheel -->
  <joint name="front_left_wheel_joint" type="continuous">
    <axis xyz="0 1 0"/>
    <parent link="steering_link"/>
    <child link="front_left_wheel_link"/>
    <origin rpy="0 0 0" xyz="0 0.1 0"/>
  </joint>
  <link name="front_left_wheel_link">
    <inertial>
      <mass value="0.01"/>
      <origin xyz="0 0 0"/>
      <inertia ixx="0.01" ixy="0.0" ixz="0.0" iyy="0.01" iyz="0.0" izz="0.01"/>
    </inertial>
    <visual>
      <origin rpy="1.57079632679 0 0" xyz="0 0 0"/>
      <geometry>
        <cylinder length="0.025" radius="0.03"/>
      </geometry>
      <material name="Green"/>
    </visual>
    <collision>
      <origin rpy="1.57079632679 0 0" xyz="0 0 0"/>
      <geometry>
        <cylinder length="0.025" radius="0.03"/>
      </geometry>
    </collision>
  </link>
  <!-- the front right wheel -->
  <joint name="front_right_wheel_joint" type="continuous">
    <axis xyz="0 1 0"/>
    <parent link="steering_link"/>
    <child link="front_right_wheel_link"/>
    <origin rpy="0 0 0" xyz="0 -0.1 0"/>
  </joint>
  <link name="front_right_wheel_link">
    <inertial>
      <mass value="0.01"/>
      <origin xyz="0 0 0"/>
      <inertia ixx="0.01" ixy="0.0" ixz="0.0" iyy="0.01" iyz="0.0" izz="0.01"/>
    </inertial>
    <visual>
      <origin rpy="1.57079632679 0 0" xyz="0 0 0"/>
      <geometry>
        <cylinder length="0.025" radius="0.03"/>
      </geometry>
      <material name="Green"/>
    </visual>
    <collision>
      <origin rpy="1.57079632679 0 0" xyz="0 0 0"/>
      <geometry>
        <cylinder length="0.025" radius="0.03"/>
      </geometry>
    </collision>
  </link>

  <!-- rear left wheel -->
  <joint name="rear_left_wheel_joint" type="continuous">
    <axis xyz="0 1 0"/>
    <parent link="base_link"/>
    <child link="rear_left_wheel_link"/>
    <origin rpy="0 0 0" xyz="-0.16 0.1 -0.1"/>
  </joint>
  <link name="rear_left_wheel_link">
    <inertial>
      <mass value="0.01"/>
      <origin xyz="0 0 0"/>
      <inertia ixx="0.01" ixy="0.0" ixz="0.0" iyy="0.01" iyz="0.0" izz="0.01"/>
    </inertial>
    <visual>
      <origin rpy="1.57079632679 0 0" xyz="0 0 0"/>
      <geometry>
        <cylinder length="0.025" radius="0.03"/>
      </geometry>
      <material name="Black"/>
    </visual>
    <collision>
      <origin rpy="1.57079632679 0 0" xyz="0 0 0"/>
      <geometry>
        <cylinder length="0.025" radius="0.03"/>
      </geometry>
    </collision>
  </link>
  <!-- rear right wheel -->
  <joint name="rear_right_wheel_joint" type="continuous">
    <axis xyz="0 1 0"/>
    <parent link="base_link"/>
    <child link="rear_right_wheel_link"/>
    <origin rpy="0 0 0" xyz="-0.16 -0.1 -0.1"/>
  </joint>
  <link name="rear_right_wheel_link">
    <inertial>
      <mass value="0.01"/>
      <origin xyz="0 0 0"/>
      <inertia ixx="0.01" ixy="0.0" ixz="0.0" iyy="0.01" iyz="0.0" izz="0.01"/>
    </inertial>
    <visual>
      <origin rpy="1.57079632679 0 0" xyz="0 0 0"/>
      <geometry>
        <cylinder length="0.025" radius="0.03"/>
      </geometry>
      <material name="Black"/>
    </visual>
    <collision>
      <origin rpy="1.57079632679 0 0" xyz="0 0 0"/>
      <geometry>
        <cylinder length="0.025" radius="0.03"/>
      </geometry>
    </collision>
  </link>
</robot>

